[2025-10-11T14:55:21.569+0300] {local_task_job_runner.py:123} INFO - ::group::Pre task execution logs
[2025-10-11T14:55:21.580+0300] {taskinstance.py:2612} INFO - Dependencies all met for dep_context=non-requeueable deps ti=<TaskInstance: cafe_sales_etl.generate_reports manual__2025-10-11T11:49:58.125072+00:00 [queued]>
[2025-10-11T14:55:21.586+0300] {taskinstance.py:2612} INFO - Dependencies all met for dep_context=requeueable deps ti=<TaskInstance: cafe_sales_etl.generate_reports manual__2025-10-11T11:49:58.125072+00:00 [queued]>
[2025-10-11T14:55:21.587+0300] {taskinstance.py:2865} INFO - Starting attempt 2 of 2
[2025-10-11T14:55:21.604+0300] {taskinstance.py:2888} INFO - Executing <Task(PythonOperator): generate_reports> on 2025-10-11 11:49:58.125072+00:00
[2025-10-11T14:55:21.610+0300] {standard_task_runner.py:72} INFO - Started process 67821 to run task
[2025-10-11T14:55:21.613+0300] {standard_task_runner.py:104} INFO - Running: ['airflow', 'tasks', 'run', 'cafe_sales_etl', 'generate_reports', 'manual__2025-10-11T11:49:58.125072+00:00', '--job-id', '102', '--raw', '--subdir', 'DAGS_FOLDER/cafe_sales_etl_dag.py', '--cfg-path', '/tmp/tmpr43uzjyf']
[2025-10-11T14:55:21.614+0300] {standard_task_runner.py:105} INFO - Job 102: Subtask generate_reports
[2025-10-11T14:55:21.655+0300] {task_command.py:467} INFO - Running <TaskInstance: cafe_sales_etl.generate_reports manual__2025-10-11T11:49:58.125072+00:00 [running]> on host archlinux
[2025-10-11T14:55:21.713+0300] {taskinstance.py:3131} INFO - Exporting env vars: AIRFLOW_CTX_DAG_OWNER='airflow' AIRFLOW_CTX_DAG_ID='cafe_sales_etl' AIRFLOW_CTX_TASK_ID='generate_reports' AIRFLOW_CTX_EXECUTION_DATE='2025-10-11T11:49:58.125072+00:00' AIRFLOW_CTX_TRY_NUMBER='2' AIRFLOW_CTX_DAG_RUN_ID='manual__2025-10-11T11:49:58.125072+00:00'
[2025-10-11T14:55:21.714+0300] {logging_mixin.py:190} INFO - Task instance is in running state
[2025-10-11T14:55:21.714+0300] {logging_mixin.py:190} INFO -  Previous state of the Task instance: queued
[2025-10-11T14:55:21.714+0300] {logging_mixin.py:190} INFO - Current task name:generate_reports state:running start_date:2025-10-11 11:55:21.581144+00:00
[2025-10-11T14:55:21.715+0300] {logging_mixin.py:190} INFO - Dag name:cafe_sales_etl and current dag run status:running
[2025-10-11T14:55:21.715+0300] {taskinstance.py:731} INFO - ::endgroup::
[2025-10-11T14:55:21.734+0300] {logging_mixin.py:190} INFO - ✅ Report saved: top_items.csv
[2025-10-11T14:55:21.738+0300] {logging_mixin.py:190} INFO - ✅ Report saved: revenue_by_location.csv
[2025-10-11T14:55:21.744+0300] {taskinstance.py:3310} ERROR - Task failed with exception
Traceback (most recent call last):
  File "/home/hsooni/cafe_sales_etl/venv/lib/python3.12/site-packages/airflow/models/taskinstance.py", line 767, in _execute_task
    result = _execute_callable(context=context, **execute_callable_kwargs)
             ^^^^^^^^^^^^^^^^^^^^^^^^^^^^^^^^^^^^^^^^^^^^^^^^^^^^^^^^^^^^^
  File "/home/hsooni/cafe_sales_etl/venv/lib/python3.12/site-packages/airflow/models/taskinstance.py", line 733, in _execute_callable
    return ExecutionCallableRunner(
           ^^^^^^^^^^^^^^^^^^^^^^^^
  File "/home/hsooni/cafe_sales_etl/venv/lib/python3.12/site-packages/airflow/utils/operator_helpers.py", line 252, in run
    return self.func(*args, **kwargs)
           ^^^^^^^^^^^^^^^^^^^^^^^^^^
  File "/home/hsooni/cafe_sales_etl/venv/lib/python3.12/site-packages/airflow/models/baseoperator.py", line 406, in wrapper
    return func(self, *args, **kwargs)
           ^^^^^^^^^^^^^^^^^^^^^^^^^^^
  File "/home/hsooni/cafe_sales_etl/venv/lib/python3.12/site-packages/airflow/operators/python.py", line 238, in execute
    return_value = self.execute_callable()
                   ^^^^^^^^^^^^^^^^^^^^^^^
  File "/home/hsooni/cafe_sales_etl/venv/lib/python3.12/site-packages/airflow/operators/python.py", line 256, in execute_callable
    return runner.run(*self.op_args, **self.op_kwargs)
           ^^^^^^^^^^^^^^^^^^^^^^^^^^^^^^^^^^^^^^^^^^^
  File "/home/hsooni/cafe_sales_etl/venv/lib/python3.12/site-packages/airflow/utils/operator_helpers.py", line 252, in run
    return self.func(*args, **kwargs)
           ^^^^^^^^^^^^^^^^^^^^^^^^^^
  File "/home/hsooni/cafe_sales_etl/airflow/dags/cafe_sales_etl_dag.py", line 120, in run_sql_reports
    df = pd.DataFrame(result.fetchall(), columns=result.keys())
                      ^^^^^^^^^^^^^^^^^
  File "/home/hsooni/cafe_sales_etl/venv/lib/python3.12/site-packages/sqlalchemy/engine/result.py", line 1072, in fetchall
    return self._allrows()
           ^^^^^^^^^^^^^^^
  File "/home/hsooni/cafe_sales_etl/venv/lib/python3.12/site-packages/sqlalchemy/engine/result.py", line 401, in _allrows
    rows = self._fetchall_impl()
           ^^^^^^^^^^^^^^^^^^^^^
  File "/home/hsooni/cafe_sales_etl/venv/lib/python3.12/site-packages/sqlalchemy/engine/cursor.py", line 1819, in _fetchall_impl
    return self.cursor_strategy.fetchall(self, self.cursor)
           ^^^^^^^^^^^^^^^^^^^^^^^^^^^^^^^^^^^^^^^^^^^^^^^^
  File "/home/hsooni/cafe_sales_etl/venv/lib/python3.12/site-packages/sqlalchemy/engine/cursor.py", line 995, in fetchall
    self.handle_exception(result, dbapi_cursor, e)
  File "/home/hsooni/cafe_sales_etl/venv/lib/python3.12/site-packages/sqlalchemy/engine/cursor.py", line 955, in handle_exception
    result.connection._handle_dbapi_exception(
  File "/home/hsooni/cafe_sales_etl/venv/lib/python3.12/site-packages/sqlalchemy/engine/base.py", line 2138, in _handle_dbapi_exception
    util.raise_(exc_info[1], with_traceback=exc_info[2])
  File "/home/hsooni/cafe_sales_etl/venv/lib/python3.12/site-packages/sqlalchemy/util/compat.py", line 211, in raise_
    raise exception
  File "/home/hsooni/cafe_sales_etl/venv/lib/python3.12/site-packages/sqlalchemy/engine/cursor.py", line 991, in fetchall
    rows = dbapi_cursor.fetchall()
           ^^^^^^^^^^^^^^^^^^^^^^^
ValueError: year 54970 is out of range
[2025-10-11T14:55:21.752+0300] {logging_mixin.py:190} INFO - Task instance in failure state
[2025-10-11T14:55:21.752+0300] {logging_mixin.py:190} INFO - Task start:2025-10-11 11:55:21.581144+00:00 end:2025-10-11 11:55:21.751448+00:00 duration:0.170304
[2025-10-11T14:55:21.752+0300] {logging_mixin.py:190} INFO - Task:<Task(PythonOperator): generate_reports> dag:<DAG: cafe_sales_etl> dagrun:<DagRun cafe_sales_etl @ 2025-10-11 11:49:58.125072+00:00: manual__2025-10-11T11:49:58.125072+00:00, state:running, queued_at: 2025-10-11 11:49:58.135310+00:00. externally triggered: True>
[2025-10-11T14:55:21.752+0300] {logging_mixin.py:190} INFO - Failure caused by year 54970 is out of range
[2025-10-11T14:55:21.753+0300] {taskinstance.py:1225} INFO - Marking task as FAILED. dag_id=cafe_sales_etl, task_id=generate_reports, run_id=manual__2025-10-11T11:49:58.125072+00:00, execution_date=20251011T114958, start_date=20251011T115521, end_date=20251011T115521
[2025-10-11T14:55:21.773+0300] {taskinstance.py:340} INFO - ::group::Post task execution logs
[2025-10-11T14:55:21.773+0300] {standard_task_runner.py:124} ERROR - Failed to execute job 102 for task generate_reports (year 54970 is out of range; 67821)
Traceback (most recent call last):
  File "/home/hsooni/cafe_sales_etl/venv/lib/python3.12/site-packages/airflow/task/task_runner/standard_task_runner.py", line 117, in _start_by_fork
    ret = args.func(args, dag=self.dag)
          ^^^^^^^^^^^^^^^^^^^^^^^^^^^^^
  File "/home/hsooni/cafe_sales_etl/venv/lib/python3.12/site-packages/airflow/cli/cli_config.py", line 49, in command
    return func(*args, **kwargs)
           ^^^^^^^^^^^^^^^^^^^^^
  File "/home/hsooni/cafe_sales_etl/venv/lib/python3.12/site-packages/airflow/utils/cli.py", line 115, in wrapper
    return f(*args, **kwargs)
           ^^^^^^^^^^^^^^^^^^
  File "/home/hsooni/cafe_sales_etl/venv/lib/python3.12/site-packages/airflow/cli/commands/task_command.py", line 483, in task_run
    task_return_code = _run_task_by_selected_method(args, _dag, ti)
                       ^^^^^^^^^^^^^^^^^^^^^^^^^^^^^^^^^^^^^^^^^^^^
  File "/home/hsooni/cafe_sales_etl/venv/lib/python3.12/site-packages/airflow/cli/commands/task_command.py", line 256, in _run_task_by_selected_method
    return _run_raw_task(args, ti)
           ^^^^^^^^^^^^^^^^^^^^^^^
  File "/home/hsooni/cafe_sales_etl/venv/lib/python3.12/site-packages/airflow/cli/commands/task_command.py", line 341, in _run_raw_task
    return ti._run_raw_task(
           ^^^^^^^^^^^^^^^^^
  File "/home/hsooni/cafe_sales_etl/venv/lib/python3.12/site-packages/airflow/utils/session.py", line 97, in wrapper
    return func(*args, session=session, **kwargs)
           ^^^^^^^^^^^^^^^^^^^^^^^^^^^^^^^^^^^^^^
  File "/home/hsooni/cafe_sales_etl/venv/lib/python3.12/site-packages/airflow/models/taskinstance.py", line 3004, in _run_raw_task
    return _run_raw_task(
           ^^^^^^^^^^^^^^
  File "/home/hsooni/cafe_sales_etl/venv/lib/python3.12/site-packages/airflow/models/taskinstance.py", line 273, in _run_raw_task
    TaskInstance._execute_task_with_callbacks(
  File "/home/hsooni/cafe_sales_etl/venv/lib/python3.12/site-packages/airflow/models/taskinstance.py", line 3158, in _execute_task_with_callbacks
    result = self._execute_task(context, task_orig)
             ^^^^^^^^^^^^^^^^^^^^^^^^^^^^^^^^^^^^^^
  File "/home/hsooni/cafe_sales_etl/venv/lib/python3.12/site-packages/airflow/models/taskinstance.py", line 3182, in _execute_task
    return _execute_task(self, context, task_orig)
           ^^^^^^^^^^^^^^^^^^^^^^^^^^^^^^^^^^^^^^^
  File "/home/hsooni/cafe_sales_etl/venv/lib/python3.12/site-packages/airflow/models/taskinstance.py", line 767, in _execute_task
    result = _execute_callable(context=context, **execute_callable_kwargs)
             ^^^^^^^^^^^^^^^^^^^^^^^^^^^^^^^^^^^^^^^^^^^^^^^^^^^^^^^^^^^^^
  File "/home/hsooni/cafe_sales_etl/venv/lib/python3.12/site-packages/airflow/models/taskinstance.py", line 733, in _execute_callable
    return ExecutionCallableRunner(
           ^^^^^^^^^^^^^^^^^^^^^^^^
  File "/home/hsooni/cafe_sales_etl/venv/lib/python3.12/site-packages/airflow/utils/operator_helpers.py", line 252, in run
    return self.func(*args, **kwargs)
           ^^^^^^^^^^^^^^^^^^^^^^^^^^
  File "/home/hsooni/cafe_sales_etl/venv/lib/python3.12/site-packages/airflow/models/baseoperator.py", line 406, in wrapper
    return func(self, *args, **kwargs)
           ^^^^^^^^^^^^^^^^^^^^^^^^^^^
  File "/home/hsooni/cafe_sales_etl/venv/lib/python3.12/site-packages/airflow/operators/python.py", line 238, in execute
    return_value = self.execute_callable()
                   ^^^^^^^^^^^^^^^^^^^^^^^
  File "/home/hsooni/cafe_sales_etl/venv/lib/python3.12/site-packages/airflow/operators/python.py", line 256, in execute_callable
    return runner.run(*self.op_args, **self.op_kwargs)
           ^^^^^^^^^^^^^^^^^^^^^^^^^^^^^^^^^^^^^^^^^^^
  File "/home/hsooni/cafe_sales_etl/venv/lib/python3.12/site-packages/airflow/utils/operator_helpers.py", line 252, in run
    return self.func(*args, **kwargs)
           ^^^^^^^^^^^^^^^^^^^^^^^^^^
  File "/home/hsooni/cafe_sales_etl/airflow/dags/cafe_sales_etl_dag.py", line 120, in run_sql_reports
    df = pd.DataFrame(result.fetchall(), columns=result.keys())
                      ^^^^^^^^^^^^^^^^^
  File "/home/hsooni/cafe_sales_etl/venv/lib/python3.12/site-packages/sqlalchemy/engine/result.py", line 1072, in fetchall
    return self._allrows()
           ^^^^^^^^^^^^^^^
  File "/home/hsooni/cafe_sales_etl/venv/lib/python3.12/site-packages/sqlalchemy/engine/result.py", line 401, in _allrows
    rows = self._fetchall_impl()
           ^^^^^^^^^^^^^^^^^^^^^
  File "/home/hsooni/cafe_sales_etl/venv/lib/python3.12/site-packages/sqlalchemy/engine/cursor.py", line 1819, in _fetchall_impl
    return self.cursor_strategy.fetchall(self, self.cursor)
           ^^^^^^^^^^^^^^^^^^^^^^^^^^^^^^^^^^^^^^^^^^^^^^^^
  File "/home/hsooni/cafe_sales_etl/venv/lib/python3.12/site-packages/sqlalchemy/engine/cursor.py", line 995, in fetchall
    self.handle_exception(result, dbapi_cursor, e)
  File "/home/hsooni/cafe_sales_etl/venv/lib/python3.12/site-packages/sqlalchemy/engine/cursor.py", line 955, in handle_exception
    result.connection._handle_dbapi_exception(
  File "/home/hsooni/cafe_sales_etl/venv/lib/python3.12/site-packages/sqlalchemy/engine/base.py", line 2138, in _handle_dbapi_exception
    util.raise_(exc_info[1], with_traceback=exc_info[2])
  File "/home/hsooni/cafe_sales_etl/venv/lib/python3.12/site-packages/sqlalchemy/util/compat.py", line 211, in raise_
    raise exception
  File "/home/hsooni/cafe_sales_etl/venv/lib/python3.12/site-packages/sqlalchemy/engine/cursor.py", line 991, in fetchall
    rows = dbapi_cursor.fetchall()
           ^^^^^^^^^^^^^^^^^^^^^^^
ValueError: year 54970 is out of range
[2025-10-11T14:55:21.785+0300] {local_task_job_runner.py:266} INFO - Task exited with return code 1
[2025-10-11T14:55:21.804+0300] {taskinstance.py:3900} INFO - 0 downstream tasks scheduled from follow-on schedule check
[2025-10-11T14:55:21.816+0300] {local_task_job_runner.py:245} INFO - ::endgroup::
