[2025-10-11T14:33:18.767+0300] {local_task_job_runner.py:123} INFO - ::group::Pre task execution logs
[2025-10-11T14:33:18.780+0300] {taskinstance.py:2612} INFO - Dependencies all met for dep_context=non-requeueable deps ti=<TaskInstance: cafe_sales_etl.load_to_postgres manual__2025-10-11T11:33:07.358953+00:00 [queued]>
[2025-10-11T14:33:18.788+0300] {taskinstance.py:2612} INFO - Dependencies all met for dep_context=requeueable deps ti=<TaskInstance: cafe_sales_etl.load_to_postgres manual__2025-10-11T11:33:07.358953+00:00 [queued]>
[2025-10-11T14:33:18.788+0300] {taskinstance.py:2865} INFO - Starting attempt 1 of 2
[2025-10-11T14:33:18.808+0300] {taskinstance.py:2888} INFO - Executing <Task(PythonOperator): load_to_postgres> on 2025-10-11 11:33:07.358953+00:00
[2025-10-11T14:33:18.813+0300] {standard_task_runner.py:72} INFO - Started process 55683 to run task
[2025-10-11T14:33:18.816+0300] {standard_task_runner.py:104} INFO - Running: ['airflow', 'tasks', 'run', 'cafe_sales_etl', 'load_to_postgres', 'manual__2025-10-11T11:33:07.358953+00:00', '--job-id', '45', '--raw', '--subdir', 'DAGS_FOLDER/cafe_sales_etl_dag.py', '--cfg-path', '/tmp/tmpm8x5ercj']
[2025-10-11T14:33:18.817+0300] {standard_task_runner.py:105} INFO - Job 45: Subtask load_to_postgres
[2025-10-11T14:33:18.862+0300] {task_command.py:467} INFO - Running <TaskInstance: cafe_sales_etl.load_to_postgres manual__2025-10-11T11:33:07.358953+00:00 [running]> on host archlinux
[2025-10-11T14:33:18.930+0300] {taskinstance.py:3131} INFO - Exporting env vars: AIRFLOW_CTX_DAG_OWNER='airflow' AIRFLOW_CTX_DAG_ID='cafe_sales_etl' AIRFLOW_CTX_TASK_ID='load_to_postgres' AIRFLOW_CTX_EXECUTION_DATE='2025-10-11T11:33:07.358953+00:00' AIRFLOW_CTX_TRY_NUMBER='1' AIRFLOW_CTX_DAG_RUN_ID='manual__2025-10-11T11:33:07.358953+00:00'
[2025-10-11T14:33:18.931+0300] {logging_mixin.py:190} INFO - Task instance is in running state
[2025-10-11T14:33:18.932+0300] {logging_mixin.py:190} INFO -  Previous state of the Task instance: queued
[2025-10-11T14:33:18.932+0300] {logging_mixin.py:190} INFO - Current task name:load_to_postgres state:running start_date:2025-10-11 11:33:18.780447+00:00
[2025-10-11T14:33:18.932+0300] {logging_mixin.py:190} INFO - Dag name:cafe_sales_etl and current dag run status:running
[2025-10-11T14:33:18.932+0300] {taskinstance.py:731} INFO - ::endgroup::
[2025-10-11T14:33:19.037+0300] {taskinstance.py:3310} ERROR - Task failed with exception
Traceback (most recent call last):
  File "/home/hsooni/cafe_sales_etl/utils/pipeline_utils.py", line 88, in load_to_postgres
    cur.executemany(insert_stmt, data)
psycopg2.errors.NumericValueOutOfRange: integer out of range


During handling of the above exception, another exception occurred:

Traceback (most recent call last):
  File "/home/hsooni/cafe_sales_etl/venv/lib/python3.12/site-packages/airflow/models/taskinstance.py", line 767, in _execute_task
    result = _execute_callable(context=context, **execute_callable_kwargs)
             ^^^^^^^^^^^^^^^^^^^^^^^^^^^^^^^^^^^^^^^^^^^^^^^^^^^^^^^^^^^^^
  File "/home/hsooni/cafe_sales_etl/venv/lib/python3.12/site-packages/airflow/models/taskinstance.py", line 733, in _execute_callable
    return ExecutionCallableRunner(
           ^^^^^^^^^^^^^^^^^^^^^^^^
  File "/home/hsooni/cafe_sales_etl/venv/lib/python3.12/site-packages/airflow/utils/operator_helpers.py", line 252, in run
    return self.func(*args, **kwargs)
           ^^^^^^^^^^^^^^^^^^^^^^^^^^
  File "/home/hsooni/cafe_sales_etl/venv/lib/python3.12/site-packages/airflow/models/baseoperator.py", line 406, in wrapper
    return func(self, *args, **kwargs)
           ^^^^^^^^^^^^^^^^^^^^^^^^^^^
  File "/home/hsooni/cafe_sales_etl/venv/lib/python3.12/site-packages/airflow/operators/python.py", line 238, in execute
    return_value = self.execute_callable()
                   ^^^^^^^^^^^^^^^^^^^^^^^
  File "/home/hsooni/cafe_sales_etl/venv/lib/python3.12/site-packages/airflow/operators/python.py", line 256, in execute_callable
    return runner.run(*self.op_args, **self.op_kwargs)
           ^^^^^^^^^^^^^^^^^^^^^^^^^^^^^^^^^^^^^^^^^^^
  File "/home/hsooni/cafe_sales_etl/venv/lib/python3.12/site-packages/airflow/utils/operator_helpers.py", line 252, in run
    return self.func(*args, **kwargs)
           ^^^^^^^^^^^^^^^^^^^^^^^^^^
  File "/home/hsooni/cafe_sales_etl/airflow/dags/cafe_sales_etl_dag.py", line 74, in load_task
    load_to_postgres(df)
  File "/home/hsooni/cafe_sales_etl/utils/pipeline_utils.py", line 97, in load_to_postgres
    raise RuntimeError(f"❌ Failed to load data into PostgreSQL: {e}")
RuntimeError: ❌ Failed to load data into PostgreSQL: integer out of range

[2025-10-11T14:33:19.045+0300] {logging_mixin.py:190} INFO - Task instance in failure state
[2025-10-11T14:33:19.046+0300] {logging_mixin.py:190} INFO - Task start:2025-10-11 11:33:18.780447+00:00 end:2025-10-11 11:33:19.045379+00:00 duration:0.264932
[2025-10-11T14:33:19.046+0300] {logging_mixin.py:190} INFO - Task:<Task(PythonOperator): load_to_postgres> dag:<DAG: cafe_sales_etl> dagrun:<DagRun cafe_sales_etl @ 2025-10-11 11:33:07.358953+00:00: manual__2025-10-11T11:33:07.358953+00:00, state:running, queued_at: 2025-10-11 11:33:07.375096+00:00. externally triggered: True>
[2025-10-11T14:33:19.046+0300] {logging_mixin.py:190} INFO - Failure caused by ❌ Failed to load data into PostgreSQL: integer out of range
[2025-10-11T14:33:19.046+0300] {taskinstance.py:1225} INFO - Marking task as UP_FOR_RETRY. dag_id=cafe_sales_etl, task_id=load_to_postgres, run_id=manual__2025-10-11T11:33:07.358953+00:00, execution_date=20251011T113307, start_date=20251011T113318, end_date=20251011T113319
[2025-10-11T14:33:19.065+0300] {taskinstance.py:340} INFO - ::group::Post task execution logs
[2025-10-11T14:33:19.065+0300] {standard_task_runner.py:124} ERROR - Failed to execute job 45 for task load_to_postgres (❌ Failed to load data into PostgreSQL: integer out of range
; 55683)
Traceback (most recent call last):
  File "/home/hsooni/cafe_sales_etl/utils/pipeline_utils.py", line 88, in load_to_postgres
    cur.executemany(insert_stmt, data)
psycopg2.errors.NumericValueOutOfRange: integer out of range


During handling of the above exception, another exception occurred:

Traceback (most recent call last):
  File "/home/hsooni/cafe_sales_etl/venv/lib/python3.12/site-packages/airflow/task/task_runner/standard_task_runner.py", line 117, in _start_by_fork
    ret = args.func(args, dag=self.dag)
          ^^^^^^^^^^^^^^^^^^^^^^^^^^^^^
  File "/home/hsooni/cafe_sales_etl/venv/lib/python3.12/site-packages/airflow/cli/cli_config.py", line 49, in command
    return func(*args, **kwargs)
           ^^^^^^^^^^^^^^^^^^^^^
  File "/home/hsooni/cafe_sales_etl/venv/lib/python3.12/site-packages/airflow/utils/cli.py", line 115, in wrapper
    return f(*args, **kwargs)
           ^^^^^^^^^^^^^^^^^^
  File "/home/hsooni/cafe_sales_etl/venv/lib/python3.12/site-packages/airflow/cli/commands/task_command.py", line 483, in task_run
    task_return_code = _run_task_by_selected_method(args, _dag, ti)
                       ^^^^^^^^^^^^^^^^^^^^^^^^^^^^^^^^^^^^^^^^^^^^
  File "/home/hsooni/cafe_sales_etl/venv/lib/python3.12/site-packages/airflow/cli/commands/task_command.py", line 256, in _run_task_by_selected_method
    return _run_raw_task(args, ti)
           ^^^^^^^^^^^^^^^^^^^^^^^
  File "/home/hsooni/cafe_sales_etl/venv/lib/python3.12/site-packages/airflow/cli/commands/task_command.py", line 341, in _run_raw_task
    return ti._run_raw_task(
           ^^^^^^^^^^^^^^^^^
  File "/home/hsooni/cafe_sales_etl/venv/lib/python3.12/site-packages/airflow/utils/session.py", line 97, in wrapper
    return func(*args, session=session, **kwargs)
           ^^^^^^^^^^^^^^^^^^^^^^^^^^^^^^^^^^^^^^
  File "/home/hsooni/cafe_sales_etl/venv/lib/python3.12/site-packages/airflow/models/taskinstance.py", line 3004, in _run_raw_task
    return _run_raw_task(
           ^^^^^^^^^^^^^^
  File "/home/hsooni/cafe_sales_etl/venv/lib/python3.12/site-packages/airflow/models/taskinstance.py", line 273, in _run_raw_task
    TaskInstance._execute_task_with_callbacks(
  File "/home/hsooni/cafe_sales_etl/venv/lib/python3.12/site-packages/airflow/models/taskinstance.py", line 3158, in _execute_task_with_callbacks
    result = self._execute_task(context, task_orig)
             ^^^^^^^^^^^^^^^^^^^^^^^^^^^^^^^^^^^^^^
  File "/home/hsooni/cafe_sales_etl/venv/lib/python3.12/site-packages/airflow/models/taskinstance.py", line 3182, in _execute_task
    return _execute_task(self, context, task_orig)
           ^^^^^^^^^^^^^^^^^^^^^^^^^^^^^^^^^^^^^^^
  File "/home/hsooni/cafe_sales_etl/venv/lib/python3.12/site-packages/airflow/models/taskinstance.py", line 767, in _execute_task
    result = _execute_callable(context=context, **execute_callable_kwargs)
             ^^^^^^^^^^^^^^^^^^^^^^^^^^^^^^^^^^^^^^^^^^^^^^^^^^^^^^^^^^^^^
  File "/home/hsooni/cafe_sales_etl/venv/lib/python3.12/site-packages/airflow/models/taskinstance.py", line 733, in _execute_callable
    return ExecutionCallableRunner(
           ^^^^^^^^^^^^^^^^^^^^^^^^
  File "/home/hsooni/cafe_sales_etl/venv/lib/python3.12/site-packages/airflow/utils/operator_helpers.py", line 252, in run
    return self.func(*args, **kwargs)
           ^^^^^^^^^^^^^^^^^^^^^^^^^^
  File "/home/hsooni/cafe_sales_etl/venv/lib/python3.12/site-packages/airflow/models/baseoperator.py", line 406, in wrapper
    return func(self, *args, **kwargs)
           ^^^^^^^^^^^^^^^^^^^^^^^^^^^
  File "/home/hsooni/cafe_sales_etl/venv/lib/python3.12/site-packages/airflow/operators/python.py", line 238, in execute
    return_value = self.execute_callable()
                   ^^^^^^^^^^^^^^^^^^^^^^^
  File "/home/hsooni/cafe_sales_etl/venv/lib/python3.12/site-packages/airflow/operators/python.py", line 256, in execute_callable
    return runner.run(*self.op_args, **self.op_kwargs)
           ^^^^^^^^^^^^^^^^^^^^^^^^^^^^^^^^^^^^^^^^^^^
  File "/home/hsooni/cafe_sales_etl/venv/lib/python3.12/site-packages/airflow/utils/operator_helpers.py", line 252, in run
    return self.func(*args, **kwargs)
           ^^^^^^^^^^^^^^^^^^^^^^^^^^
  File "/home/hsooni/cafe_sales_etl/airflow/dags/cafe_sales_etl_dag.py", line 74, in load_task
    load_to_postgres(df)
  File "/home/hsooni/cafe_sales_etl/utils/pipeline_utils.py", line 97, in load_to_postgres
    raise RuntimeError(f"❌ Failed to load data into PostgreSQL: {e}")
RuntimeError: ❌ Failed to load data into PostgreSQL: integer out of range

[2025-10-11T14:33:19.111+0300] {local_task_job_runner.py:266} INFO - Task exited with return code 1
[2025-10-11T14:33:19.147+0300] {taskinstance.py:3900} INFO - 0 downstream tasks scheduled from follow-on schedule check
[2025-10-11T14:33:19.148+0300] {local_task_job_runner.py:245} INFO - ::endgroup::
