[2025-10-11T14:52:53.132+0300] {local_task_job_runner.py:123} INFO - ::group::Pre task execution logs
[2025-10-11T14:52:53.144+0300] {taskinstance.py:2612} INFO - Dependencies all met for dep_context=non-requeueable deps ti=<TaskInstance: cafe_sales_etl.generate_reports manual__2025-10-11T11:47:29.231427+00:00 [queued]>
[2025-10-11T14:52:53.150+0300] {taskinstance.py:2612} INFO - Dependencies all met for dep_context=requeueable deps ti=<TaskInstance: cafe_sales_etl.generate_reports manual__2025-10-11T11:47:29.231427+00:00 [queued]>
[2025-10-11T14:52:53.150+0300] {taskinstance.py:2865} INFO - Starting attempt 2 of 2
[2025-10-11T14:52:53.168+0300] {taskinstance.py:2888} INFO - Executing <Task(PythonOperator): generate_reports> on 2025-10-11 11:47:29.231427+00:00
[2025-10-11T14:52:53.174+0300] {standard_task_runner.py:72} INFO - Started process 66511 to run task
[2025-10-11T14:52:53.176+0300] {standard_task_runner.py:104} INFO - Running: ['airflow', 'tasks', 'run', 'cafe_sales_etl', 'generate_reports', 'manual__2025-10-11T11:47:29.231427+00:00', '--job-id', '95', '--raw', '--subdir', 'DAGS_FOLDER/cafe_sales_etl_dag.py', '--cfg-path', '/tmp/tmp48x1jlm5']
[2025-10-11T14:52:53.177+0300] {standard_task_runner.py:105} INFO - Job 95: Subtask generate_reports
[2025-10-11T14:52:53.220+0300] {task_command.py:467} INFO - Running <TaskInstance: cafe_sales_etl.generate_reports manual__2025-10-11T11:47:29.231427+00:00 [running]> on host archlinux
[2025-10-11T14:52:53.277+0300] {taskinstance.py:3131} INFO - Exporting env vars: AIRFLOW_CTX_DAG_OWNER='airflow' AIRFLOW_CTX_DAG_ID='cafe_sales_etl' AIRFLOW_CTX_TASK_ID='generate_reports' AIRFLOW_CTX_EXECUTION_DATE='2025-10-11T11:47:29.231427+00:00' AIRFLOW_CTX_TRY_NUMBER='2' AIRFLOW_CTX_DAG_RUN_ID='manual__2025-10-11T11:47:29.231427+00:00'
[2025-10-11T14:52:53.278+0300] {logging_mixin.py:190} INFO - Task instance is in running state
[2025-10-11T14:52:53.278+0300] {logging_mixin.py:190} INFO -  Previous state of the Task instance: queued
[2025-10-11T14:52:53.278+0300] {logging_mixin.py:190} INFO - Current task name:generate_reports state:running start_date:2025-10-11 11:52:53.144532+00:00
[2025-10-11T14:52:53.279+0300] {logging_mixin.py:190} INFO - Dag name:cafe_sales_etl and current dag run status:running
[2025-10-11T14:52:53.279+0300] {taskinstance.py:731} INFO - ::endgroup::
[2025-10-11T14:52:53.297+0300] {logging_mixin.py:190} INFO - ✅ Report saved: top_items.csv
[2025-10-11T14:52:53.302+0300] {logging_mixin.py:190} INFO - ✅ Report saved: revenue_by_location.csv
[2025-10-11T14:52:53.303+0300] {taskinstance.py:3310} ERROR - Task failed with exception
Traceback (most recent call last):
  File "/home/hsooni/cafe_sales_etl/venv/lib/python3.12/site-packages/sqlalchemy/engine/base.py", line 1910, in _execute_context
    self.dialect.do_execute(
  File "/home/hsooni/cafe_sales_etl/venv/lib/python3.12/site-packages/sqlalchemy/engine/default.py", line 736, in do_execute
    cursor.execute(statement, parameters)
psycopg2.errors.UndefinedFunction: function date(bigint) does not exist
LINE 2:     DATE(transaction_date) AS day,
            ^
HINT:  No function matches the given name and argument types. You might need to add explicit type casts.


The above exception was the direct cause of the following exception:

Traceback (most recent call last):
  File "/home/hsooni/cafe_sales_etl/venv/lib/python3.12/site-packages/airflow/models/taskinstance.py", line 767, in _execute_task
    result = _execute_callable(context=context, **execute_callable_kwargs)
             ^^^^^^^^^^^^^^^^^^^^^^^^^^^^^^^^^^^^^^^^^^^^^^^^^^^^^^^^^^^^^
  File "/home/hsooni/cafe_sales_etl/venv/lib/python3.12/site-packages/airflow/models/taskinstance.py", line 733, in _execute_callable
    return ExecutionCallableRunner(
           ^^^^^^^^^^^^^^^^^^^^^^^^
  File "/home/hsooni/cafe_sales_etl/venv/lib/python3.12/site-packages/airflow/utils/operator_helpers.py", line 252, in run
    return self.func(*args, **kwargs)
           ^^^^^^^^^^^^^^^^^^^^^^^^^^
  File "/home/hsooni/cafe_sales_etl/venv/lib/python3.12/site-packages/airflow/models/baseoperator.py", line 406, in wrapper
    return func(self, *args, **kwargs)
           ^^^^^^^^^^^^^^^^^^^^^^^^^^^
  File "/home/hsooni/cafe_sales_etl/venv/lib/python3.12/site-packages/airflow/operators/python.py", line 238, in execute
    return_value = self.execute_callable()
                   ^^^^^^^^^^^^^^^^^^^^^^^
  File "/home/hsooni/cafe_sales_etl/venv/lib/python3.12/site-packages/airflow/operators/python.py", line 256, in execute_callable
    return runner.run(*self.op_args, **self.op_kwargs)
           ^^^^^^^^^^^^^^^^^^^^^^^^^^^^^^^^^^^^^^^^^^^
  File "/home/hsooni/cafe_sales_etl/venv/lib/python3.12/site-packages/airflow/utils/operator_helpers.py", line 252, in run
    return self.func(*args, **kwargs)
           ^^^^^^^^^^^^^^^^^^^^^^^^^^
  File "/home/hsooni/cafe_sales_etl/airflow/dags/cafe_sales_etl_dag.py", line 119, in run_sql_reports
    result = conn.execute(text(query))
             ^^^^^^^^^^^^^^^^^^^^^^^^^
  File "/home/hsooni/cafe_sales_etl/venv/lib/python3.12/site-packages/sqlalchemy/engine/base.py", line 1385, in execute
    return meth(self, multiparams, params, _EMPTY_EXECUTION_OPTS)
           ^^^^^^^^^^^^^^^^^^^^^^^^^^^^^^^^^^^^^^^^^^^^^^^^^^^^^^
  File "/home/hsooni/cafe_sales_etl/venv/lib/python3.12/site-packages/sqlalchemy/sql/elements.py", line 334, in _execute_on_connection
    return connection._execute_clauseelement(
           ^^^^^^^^^^^^^^^^^^^^^^^^^^^^^^^^^^
  File "/home/hsooni/cafe_sales_etl/venv/lib/python3.12/site-packages/sqlalchemy/engine/base.py", line 1577, in _execute_clauseelement
    ret = self._execute_context(
          ^^^^^^^^^^^^^^^^^^^^^^
  File "/home/hsooni/cafe_sales_etl/venv/lib/python3.12/site-packages/sqlalchemy/engine/base.py", line 1953, in _execute_context
    self._handle_dbapi_exception(
  File "/home/hsooni/cafe_sales_etl/venv/lib/python3.12/site-packages/sqlalchemy/engine/base.py", line 2134, in _handle_dbapi_exception
    util.raise_(
  File "/home/hsooni/cafe_sales_etl/venv/lib/python3.12/site-packages/sqlalchemy/util/compat.py", line 211, in raise_
    raise exception
  File "/home/hsooni/cafe_sales_etl/venv/lib/python3.12/site-packages/sqlalchemy/engine/base.py", line 1910, in _execute_context
    self.dialect.do_execute(
  File "/home/hsooni/cafe_sales_etl/venv/lib/python3.12/site-packages/sqlalchemy/engine/default.py", line 736, in do_execute
    cursor.execute(statement, parameters)
sqlalchemy.exc.ProgrammingError: (psycopg2.errors.UndefinedFunction) function date(bigint) does not exist
LINE 2:     DATE(transaction_date) AS day,
            ^
HINT:  No function matches the given name and argument types. You might need to add explicit type casts.

[SQL: SELECT
    DATE(transaction_date) AS day,
    COUNT(*) AS total_transactions,
    SUM(total_spent) AS daily_revenue
FROM sales_data
GROUP BY day
ORDER BY day;
]
(Background on this error at: https://sqlalche.me/e/14/f405)
[2025-10-11T14:52:53.312+0300] {logging_mixin.py:190} INFO - Task instance in failure state
[2025-10-11T14:52:53.313+0300] {logging_mixin.py:190} INFO - Task start:2025-10-11 11:52:53.144532+00:00 end:2025-10-11 11:52:53.312269+00:00 duration:0.167737
[2025-10-11T14:52:53.313+0300] {logging_mixin.py:190} INFO - Task:<Task(PythonOperator): generate_reports> dag:<DAG: cafe_sales_etl> dagrun:<DagRun cafe_sales_etl @ 2025-10-11 11:47:29.231427+00:00: manual__2025-10-11T11:47:29.231427+00:00, state:running, queued_at: 2025-10-11 11:47:29.243428+00:00. externally triggered: True>
[2025-10-11T14:52:53.313+0300] {logging_mixin.py:190} INFO - Failure caused by (psycopg2.errors.UndefinedFunction) function date(bigint) does not exist
LINE 2:     DATE(transaction_date) AS day,
            ^
HINT:  No function matches the given name and argument types. You might need to add explicit type casts.

[SQL: SELECT
    DATE(transaction_date) AS day,
    COUNT(*) AS total_transactions,
    SUM(total_spent) AS daily_revenue
FROM sales_data
GROUP BY day
ORDER BY day;
]
(Background on this error at: https://sqlalche.me/e/14/f405)
[2025-10-11T14:52:53.313+0300] {taskinstance.py:1225} INFO - Marking task as FAILED. dag_id=cafe_sales_etl, task_id=generate_reports, run_id=manual__2025-10-11T11:47:29.231427+00:00, execution_date=20251011T114729, start_date=20251011T115253, end_date=20251011T115253
[2025-10-11T14:52:53.333+0300] {taskinstance.py:340} INFO - ::group::Post task execution logs
[2025-10-11T14:52:53.334+0300] {standard_task_runner.py:124} ERROR - Failed to execute job 95 for task generate_reports ((psycopg2.errors.UndefinedFunction) function date(bigint) does not exist
LINE 2:     DATE(transaction_date) AS day,
            ^
HINT:  No function matches the given name and argument types. You might need to add explicit type casts.

[SQL: SELECT
    DATE(transaction_date) AS day,
    COUNT(*) AS total_transactions,
    SUM(total_spent) AS daily_revenue
FROM sales_data
GROUP BY day
ORDER BY day;
]
(Background on this error at: https://sqlalche.me/e/14/f405); 66511)
Traceback (most recent call last):
  File "/home/hsooni/cafe_sales_etl/venv/lib/python3.12/site-packages/sqlalchemy/engine/base.py", line 1910, in _execute_context
    self.dialect.do_execute(
  File "/home/hsooni/cafe_sales_etl/venv/lib/python3.12/site-packages/sqlalchemy/engine/default.py", line 736, in do_execute
    cursor.execute(statement, parameters)
psycopg2.errors.UndefinedFunction: function date(bigint) does not exist
LINE 2:     DATE(transaction_date) AS day,
            ^
HINT:  No function matches the given name and argument types. You might need to add explicit type casts.


The above exception was the direct cause of the following exception:

Traceback (most recent call last):
  File "/home/hsooni/cafe_sales_etl/venv/lib/python3.12/site-packages/airflow/task/task_runner/standard_task_runner.py", line 117, in _start_by_fork
    ret = args.func(args, dag=self.dag)
          ^^^^^^^^^^^^^^^^^^^^^^^^^^^^^
  File "/home/hsooni/cafe_sales_etl/venv/lib/python3.12/site-packages/airflow/cli/cli_config.py", line 49, in command
    return func(*args, **kwargs)
           ^^^^^^^^^^^^^^^^^^^^^
  File "/home/hsooni/cafe_sales_etl/venv/lib/python3.12/site-packages/airflow/utils/cli.py", line 115, in wrapper
    return f(*args, **kwargs)
           ^^^^^^^^^^^^^^^^^^
  File "/home/hsooni/cafe_sales_etl/venv/lib/python3.12/site-packages/airflow/cli/commands/task_command.py", line 483, in task_run
    task_return_code = _run_task_by_selected_method(args, _dag, ti)
                       ^^^^^^^^^^^^^^^^^^^^^^^^^^^^^^^^^^^^^^^^^^^^
  File "/home/hsooni/cafe_sales_etl/venv/lib/python3.12/site-packages/airflow/cli/commands/task_command.py", line 256, in _run_task_by_selected_method
    return _run_raw_task(args, ti)
           ^^^^^^^^^^^^^^^^^^^^^^^
  File "/home/hsooni/cafe_sales_etl/venv/lib/python3.12/site-packages/airflow/cli/commands/task_command.py", line 341, in _run_raw_task
    return ti._run_raw_task(
           ^^^^^^^^^^^^^^^^^
  File "/home/hsooni/cafe_sales_etl/venv/lib/python3.12/site-packages/airflow/utils/session.py", line 97, in wrapper
    return func(*args, session=session, **kwargs)
           ^^^^^^^^^^^^^^^^^^^^^^^^^^^^^^^^^^^^^^
  File "/home/hsooni/cafe_sales_etl/venv/lib/python3.12/site-packages/airflow/models/taskinstance.py", line 3004, in _run_raw_task
    return _run_raw_task(
           ^^^^^^^^^^^^^^
  File "/home/hsooni/cafe_sales_etl/venv/lib/python3.12/site-packages/airflow/models/taskinstance.py", line 273, in _run_raw_task
    TaskInstance._execute_task_with_callbacks(
  File "/home/hsooni/cafe_sales_etl/venv/lib/python3.12/site-packages/airflow/models/taskinstance.py", line 3158, in _execute_task_with_callbacks
    result = self._execute_task(context, task_orig)
             ^^^^^^^^^^^^^^^^^^^^^^^^^^^^^^^^^^^^^^
  File "/home/hsooni/cafe_sales_etl/venv/lib/python3.12/site-packages/airflow/models/taskinstance.py", line 3182, in _execute_task
    return _execute_task(self, context, task_orig)
           ^^^^^^^^^^^^^^^^^^^^^^^^^^^^^^^^^^^^^^^
  File "/home/hsooni/cafe_sales_etl/venv/lib/python3.12/site-packages/airflow/models/taskinstance.py", line 767, in _execute_task
    result = _execute_callable(context=context, **execute_callable_kwargs)
             ^^^^^^^^^^^^^^^^^^^^^^^^^^^^^^^^^^^^^^^^^^^^^^^^^^^^^^^^^^^^^
  File "/home/hsooni/cafe_sales_etl/venv/lib/python3.12/site-packages/airflow/models/taskinstance.py", line 733, in _execute_callable
    return ExecutionCallableRunner(
           ^^^^^^^^^^^^^^^^^^^^^^^^
  File "/home/hsooni/cafe_sales_etl/venv/lib/python3.12/site-packages/airflow/utils/operator_helpers.py", line 252, in run
    return self.func(*args, **kwargs)
           ^^^^^^^^^^^^^^^^^^^^^^^^^^
  File "/home/hsooni/cafe_sales_etl/venv/lib/python3.12/site-packages/airflow/models/baseoperator.py", line 406, in wrapper
    return func(self, *args, **kwargs)
           ^^^^^^^^^^^^^^^^^^^^^^^^^^^
  File "/home/hsooni/cafe_sales_etl/venv/lib/python3.12/site-packages/airflow/operators/python.py", line 238, in execute
    return_value = self.execute_callable()
                   ^^^^^^^^^^^^^^^^^^^^^^^
  File "/home/hsooni/cafe_sales_etl/venv/lib/python3.12/site-packages/airflow/operators/python.py", line 256, in execute_callable
    return runner.run(*self.op_args, **self.op_kwargs)
           ^^^^^^^^^^^^^^^^^^^^^^^^^^^^^^^^^^^^^^^^^^^
  File "/home/hsooni/cafe_sales_etl/venv/lib/python3.12/site-packages/airflow/utils/operator_helpers.py", line 252, in run
    return self.func(*args, **kwargs)
           ^^^^^^^^^^^^^^^^^^^^^^^^^^
  File "/home/hsooni/cafe_sales_etl/airflow/dags/cafe_sales_etl_dag.py", line 119, in run_sql_reports
    result = conn.execute(text(query))
             ^^^^^^^^^^^^^^^^^^^^^^^^^
  File "/home/hsooni/cafe_sales_etl/venv/lib/python3.12/site-packages/sqlalchemy/engine/base.py", line 1385, in execute
    return meth(self, multiparams, params, _EMPTY_EXECUTION_OPTS)
           ^^^^^^^^^^^^^^^^^^^^^^^^^^^^^^^^^^^^^^^^^^^^^^^^^^^^^^
  File "/home/hsooni/cafe_sales_etl/venv/lib/python3.12/site-packages/sqlalchemy/sql/elements.py", line 334, in _execute_on_connection
    return connection._execute_clauseelement(
           ^^^^^^^^^^^^^^^^^^^^^^^^^^^^^^^^^^
  File "/home/hsooni/cafe_sales_etl/venv/lib/python3.12/site-packages/sqlalchemy/engine/base.py", line 1577, in _execute_clauseelement
    ret = self._execute_context(
          ^^^^^^^^^^^^^^^^^^^^^^
  File "/home/hsooni/cafe_sales_etl/venv/lib/python3.12/site-packages/sqlalchemy/engine/base.py", line 1953, in _execute_context
    self._handle_dbapi_exception(
  File "/home/hsooni/cafe_sales_etl/venv/lib/python3.12/site-packages/sqlalchemy/engine/base.py", line 2134, in _handle_dbapi_exception
    util.raise_(
  File "/home/hsooni/cafe_sales_etl/venv/lib/python3.12/site-packages/sqlalchemy/util/compat.py", line 211, in raise_
    raise exception
  File "/home/hsooni/cafe_sales_etl/venv/lib/python3.12/site-packages/sqlalchemy/engine/base.py", line 1910, in _execute_context
    self.dialect.do_execute(
  File "/home/hsooni/cafe_sales_etl/venv/lib/python3.12/site-packages/sqlalchemy/engine/default.py", line 736, in do_execute
    cursor.execute(statement, parameters)
sqlalchemy.exc.ProgrammingError: (psycopg2.errors.UndefinedFunction) function date(bigint) does not exist
LINE 2:     DATE(transaction_date) AS day,
            ^
HINT:  No function matches the given name and argument types. You might need to add explicit type casts.

[SQL: SELECT
    DATE(transaction_date) AS day,
    COUNT(*) AS total_transactions,
    SUM(total_spent) AS daily_revenue
FROM sales_data
GROUP BY day
ORDER BY day;
]
(Background on this error at: https://sqlalche.me/e/14/f405)
[2025-10-11T14:52:53.349+0300] {local_task_job_runner.py:266} INFO - Task exited with return code 1
[2025-10-11T14:52:53.368+0300] {taskinstance.py:3900} INFO - 0 downstream tasks scheduled from follow-on schedule check
[2025-10-11T14:52:53.377+0300] {local_task_job_runner.py:245} INFO - ::endgroup::
